Workbook

Sheet Лист1
A1: Дата | B1: Территория | C1: Товарооборот, шт | D1: Товарооборот, руб | E1: Количество складов | F1: Количество заказов | G1: Количество клиентов | H1: Товарооборот на склад | I1: Неделя | J1: Рабочие склады в неделю | K1: Товарооборот на склад на терр. по нед. (сред.) | L1: Рабочие склады на территорию | M1: Товарооборот на склад на терр. (сред.) | N1: Прим.: добавленные колонки необходимы чтобы расчитывать
A2: 43982 | B2: Самара | C2: 7944 | D2: 623971.5 | E2: {=_xlfn.XLOOKUP(1, (Лист1!$A2=Лист2!$A$2:$A$505)*(Лист1!$B2=Лист2!$B$2:$B$505),Лист2!$C$2:$C$505)} -> 15 | F2: {=_xlfn.XLOOKUP(1, (Лист1!$A2=Лист2!$A$2:$A$505)*(Лист1!$B2=Лист2!$B$2:$B$505),Лист2!$D$2:$D$505)} -> 441 | G2: {=_xlfn.XLOOKUP(1, (Лист1!$A2=Лист2!$A$2:$A$505)*(Лист1!$B2=Лист2!$B$2:$B$505),Лист2!$E$2:$E$505)} -> 368 | H2: =$D2/$E2 -> 41598.1 | I2: =WEEKNUM($A2,2) -> 22 | J2: =AVERAGEIFS($E$2:$E$505,$I$2:$I$505,$I2,$B$2:$B$505,$B2) -> 15 | K2: =$D2/$J2 -> 41598.1 | L2: =AVERAGEIFS($E$2:$E$505,$B$2:$B$505,$B2) -> 15 | M2: =$D2/$L2 -> 41598.1 | N2: товарооборот на склад в разрезе территорий и недель. Так как в опредленные
A3: 43981 | B3: Самара | C3: 10029 | D3: 787101 | E3: {=_xlfn.XLOOKUP(1, (Лист1!$A3=Лист2!$A$2:$A$505)*(Лист1!$B3=Лист2!$B$2:$B$505),Лист2!$C$2:$C$505)} -> 15 | F3: {=_xlfn.XLOOKUP(1, (Лист1!$A3=Лист2!$A$2:$A$505)*(Лист1!$B3=Лист2!$B$2:$B$505),Лист2!$D$2:$D$505)} -> 490 | G3: {=_xlfn.XLOOKUP(1, (Лист1!$A3=Лист2!$A$2:$A$505)*(Лист1!$B3=Лист2!$B$2:$B$505),Лист2!$E$2:$E$505)} -> 409 | H3: =$D3/$E3 -> 52473.4 | I3: =WEEKNUM($A3,2) -> 22 | J3: =AVERAGEIFS($E$2:$E$505,$I$2:$I$505,$I3,$B$2:$B$505,$B3) -> 15 | K3: =$D3/$J3 -> 52473.4 | L3: =AVERAGEIFS($E$2:$E$505,$B$2:$B$505,$B3) -> 15 | M3: =$D3/$L3 -> 52473.4 | N3: недели функционируют не все склады (разное количество), просто суммировать
A4: 43979 | B4: Самара | C4: 8536.5 | D4: 643944 | E4: {=_xlfn.XLOOKUP(1, (Лист1!$A4=Лист2!$A$2:$A$505)*(Лист1!$B4=Лист2!$B$2:$B$505),Лист2!$C$2:$C$505)} -> 15 | F4: {=_xlfn.XLOOKUP(1, (Лист1!$A4=Лист2!$A$2:$A$505)*(Лист1!$B4=Лист2!$B$2:$B$505),Лист2!$D$2:$D$505)} -> 464 | G4: {=_xlfn.XLOOKUP(1, (Лист1!$A4=Лист2!$A$2:$A$505)*(Лист1!$B4=Лист2!$B$2:$B$505),Лист2!$E$2:$E$505)} -> 390 | H4: =$D4/$E4 -> 42929.6 | I4: =WEEKNUM($A4,2) -> 22 | J4: =AVERAGEIFS($E$2:$E$505,$I$2:$I$505,$I4,$B$2:$B$505,$B4) -> 15 | K4: =$D4/$J4 -> 42929.6 | L4: =AVERAGEIFS($E$2:$E$505,$B$2:$B$505,$B4) -> 15 | M4: =$D4/$L4 -> 42929.6 | N4: товарооборот/кол. складов будет неверно. Поэтому, за определенные недели
A5: 43967 | B5: Кемерово | C5: 38947.5 | D5: 3395892 | E5: {=_xlfn.XLOOKUP(1, (Лист1!$A5=Лист2!$A$2:$A$505)*(Лист1!$B5=Лист2!$B$2:$B$505),Лист2!$C$2:$C$505)} -> 21 | F5: {=_xlfn.XLOOKUP(1, (Лист1!$A5=Лист2!$A$2:$A$505)*(Лист1!$B5=Лист2!$B$2:$B$505),Лист2!$D$2:$D$505)} -> 2145 | G5: {=_xlfn.XLOOKUP(1, (Лист1!$A5=Лист2!$A$2:$A$505)*(Лист1!$B5=Лист2!$B$2:$B$505),Лист2!$E$2:$E$505)} -> 1947 | H5: =$D5/$E5 -> 161709.14 | I5: =WEEKNUM($A5,2) -> 20 | J5: =AVERAGEIFS($E$2:$E$505,$I$2:$I$505,$I5,$B$2:$B$505,$B5) -> 21 | K5: =$D5/$J5 -> 161709.14 | L5: =AVERAGEIFS($E$2:$E$505,$B$2:$B$505,$B5) -> 20.285714 | M5: =$D5/$L5 -> 167403.13 | N5: и территории было взято среднее количество рабочих складов чтобы получить
A6: 43970 | B6: Кемерово | C6: 31842 | D6: 2771116.5 | E6: {=_xlfn.XLOOKUP(1, (Лист1!$A6=Лист2!$A$2:$A$505)*(Лист1!$B6=Лист2!$B$2:$B$505),Лист2!$C$2:$C$505)} -> 21 | F6: {=_xlfn.XLOOKUP(1, (Лист1!$A6=Лист2!$A$2:$A$505)*(Лист1!$B6=Лист2!$B$2:$B$505),Лист2!$D$2:$D$505)} -> 1860 | G6: {=_xlfn.XLOOKUP(1, (Лист1!$A6=Лист2!$A$2:$A$505)*(Лист1!$B6=Лист2!$B$2:$B$505),Лист2!$E$2:$E$505)} -> 1704 | H6: =$D6/$E6 -> 131957.93 | I6: =WEEKNUM($A6,2) -> 21 | J6: =AVERAGEIFS($E$2:$E$505,$I$2:$I$505,$I6,$B$2:$B$505,$B6) -> 20.857143 | K6: =$D6/$J6 -> 132861.75 | L6: =AVERAGEIFS($E$2:$E$505,$B$2:$B$505,$B6) -> 20.285714 | M6: =$D6/$L6 -> 136604.33 | N6: аггрегатную величину товарооборот/кол. складов по территориям и неделям.
A7: 43968 | B7: Кемерово | C7: 32023.5 | D7: 2882458.5 | E7: {=_xlfn.XLOOKUP(1, (Лист1!$A7=Лист2!$A$2:$A$505)*(Лист1!$B7=Лист2!$B$2:$B$505),Лист2!$C$2:$C$505)} -> 21 | F7: {=_xlfn.XLOOKUP(1, (Лист1!$A7=Лист2!$A$2:$A$505)*(Лист1!$B7=Лист2!$B$2:$B$505),Лист2!$D$2:$D$505)} -> 1874 | G7: {=_xlfn.XLOOKUP(1, (Лист1!$A7=Лист2!$A$2:$A$505)*(Лист1!$B7=Лист2!$B$2:$B$505),Лист2!$E$2:$E$505)} -> 1705 | H7: =$D7/$E7 -> 137259.93 | I7: =WEEKNUM($A7,2) -> 20 | J7: =AVERAGEIFS($E$2:$E$505,$I$2:$I$505,$I7,$B$2:$B$505,$B7) -> 21 | K7: =$D7/$J7 -> 137259.93 | L7: =AVERAGEIFS($E$2:$E$505,$B$2:$B$505,$B7) -> 20.285714 | M7: =$D7/$L7 -> 142093.02
A8: 43960 | B8: Кемерово | C8: 31147.5 | D8: 2831019 | E8: {=_xlfn.XLOOKUP(1, (Лист1!$A8=Лист2!$A$2:$A$505)*(Лист1!$B8=Лист2!$B$2:$B$505),Лист2!$C$2:$C$505)} -> 21 | F8: {=_xlfn.XLOOKUP(1, (Лист1!$A8=Лист2!$A$2:$A$505)*(Лист1!$B8=Лист2!$B$2:$B$505),Лист2!$D$2:$D$505)} -> 1735 | G8: {=_xlfn.XLOOKUP(1, (Лист1!$A8=Лист2!$A$2:$A$505)*(Лист1!$B8=Лист2!$B$2:$B$505),Лист2!$E$2:$E$505)} -> 1568 | H8: =$D8/$E8 -> 134810.43 | I8: =WEEKNUM($A8,2) -> 19 | J8: =AVERAGEIFS($E$2:$E$505,$I$2:$I$505,$I8,$B$2:$B$505,$B8) -> 20.571429 | K8: =$D8/$J8 -> 137618.98 | L8: =AVERAGEIFS($E$2:$E$505,$B$2:$B$505,$B8) -> 20.285714 | M8: =$D8/$L8 -> 139557.27 | N8: Считаем весь товарооборот в рублях
A9: 43955 | B9: Кемерово | C9: 25566 | D9: 2372310 | E9: {=_xlfn.XLOOKUP(1, (Лист1!$A9=Лист2!$A$2:$A$505)*(Лист1!$B9=Лист2!$B$2:$B$505),Лист2!$C$2:$C$505)} -> 20 | F9: {=_xlfn.XLOOKUP(1, (Лист1!$A9=Лист2!$A$2:$A$505)*(Лист1!$B9=Лист2!$B$2:$B$505),Лист2!$D$2:$D$505)} -> 1519 | G9: {=_xlfn.XLOOKUP(1, (Лист1!$A9=Лист2!$A$2:$A$505)*(Лист1!$B9=Лист2!$B$2:$B$505),Лист2!$E$2:$E$505)} -> 1372 | H9: =$D9/$E9 -> 118615.5 | I9: =WEEKNUM($A9,2) -> 19 | J9: =AVERAGEIFS($E$2:$E$505,$I$2:$I$505,$I9,$B$2:$B$505,$B9) -> 20.571429 | K9: =$D9/$J9 -> 115320.62 | L9: =AVERAGEIFS($E$2:$E$505,$B$2:$B$505,$B9) -> 20.285714 | M9: =$D9/$L9 -> 116944.86 | N9: чтоб видеть полностью выручку и эффективность
A10: 43950 | B10: Кемерово | C10: 29319 | D10: 2623480.5 | E10: {=_xlfn.XLOOKUP(1, (Лист1!$A10=Лист2!$A$2:$A$505)*(Лист1!$B10=Лист2!$B$2:$B$505),Лист2!$C$2:$C$505)} -> 18 | F10: {=_xlfn.XLOOKUP(1, (Лист1!$A10=Лист2!$A$2:$A$505)*(Лист1!$B10=Лист2!$B$2:$B$505),Лист2!$D$2:$D$505)} -> 1684 | G10: {=_xlfn.XLOOKUP(1, (Лист1!$A10=Лист2!$A$2:$A$505)*(Лист1!$B10=Лист2!$B$2:$B$505),Лист2!$E$2:$E$505)} -> 1528 | H10: =$D10/$E10 -> 145748.92 | I10: =WEEKNUM($A10,2) -> 18 | J10: =AVERAGEIFS($E$2:$E$505,$I$2:$I$505,$I10,$B$2:$B$505,$B10) -> 18.5 | K10: =$D10/$J10 -> 141809.76 | L10: =AVERAGEIFS($E$2:$E$505,$B$2:$B$505,$B10) -> 20.285714 | M10: =$D10/$L10 -> 129326.5 | N10: складов по территориям и неделям.
A11: 43953 | B11: Кемерово | C11: 29031 | D11: 2711247 | E11: {=_xlfn.XLOOKUP(1, (Лист1!$A11=Лист2!$A$2:$A$505)*(Лист1!$B11=Лист2!$B$2:$B$505),Лист2!$C$2:$C$505)} -> 18 | F11: {=_xlfn.XLOOKUP(1, (Лист1!$A11=Лист2!$A$2:$A$505)*(Лист1!$B11=Лист2!$B$2:$B$505),Лист2!$D$2:$D$505)} -> 1708 | G11: {=_xlfn.XLOOKUP(1, (Лист1!$A11=Лист2!$A$2:$A$505)*(Лист1!$B11=Лист2!$B$2:$B$505),Лист2!$E$2:$E$505)} -> 1534 | H11: =$D11/$E11 -> 150624.83 | I11: =WEEKNUM($A11,2) -> 18 | J11: =AVERAGEIFS($E$2:$E$505,$I$2:$I$505,$I11,$B$2:$B$505,$B11) -> 18.5 | K11: =$D11/$J11 -> 146553.89 | L11: =AVERAGEIFS($E$2:$E$505,$B$2:$B$505,$B11) -> 20.285714 | M11: =$D11/$L11 -> 133653.02
A12: 43977 | B12: Кемерово | C12: 33423 | D12: 2970330 | E12: {=_xlfn.XLOOKUP(1, (Лист1!$A12=Лист2!$A$2:$A$505)*(Лист1!$B12=Лист2!$B$2:$B$505),Лист2!$C$2:$C$505)} -> 20 | F12: {=_xlfn.XLOOKUP(1, (Лист1!$A12=Лист2!$A$2:$A$505)*(Лист1!$B12=Лист2!$B$2:$B$505),Лист2!$D$2:$D$505)} -> 2044 | G12: {=_xlfn.XLOOKUP(1, (Лист1!$A12=Лист2!$A$2:$A$505)*(Лист1!$B12=Лист2!$B$2:$B$505),Лист2!$E$2:$E$505)} -> 1863 | H12: =$D12/$E12 -> 148516.5 | I12: =WEEKNUM($A12,2) -> 22 | J12: =AVERAGEIFS($E$2:$E$505,$I$2:$I$505,$I12,$B$2:$B$505,$B12) -> 20.142857 | K12: =$D12/$J12 -> 147463.19 | L12: =AVERAGEIFS($E$2:$E$505,$B$2:$B$505,$B12) -> 20.285714 | M12: =$D12/$L12 -> 146424.72
A13: 43952 | B13: Кемерово | C13: 32487 | D13: 3031254 | E13: {=_xlfn.XLOOKUP(1, (Лист1!$A13=Лист2!$A$2:$A$505)*(Лист1!$B13=Лист2!$B$2:$B$505),Лист2!$C$2:$C$505)} -> 18 | F13: {=_xlfn.XLOOKUP(1, (Лист1!$A13=Лист2!$A$2:$A$505)*(Лист1!$B13=Лист2!$B$2:$B$505),Лист2!$D$2:$D$505)} -> 1826 | G13: {=_xlfn.XLOOKUP(1, (Лист1!$A13=Лист2!$A$2:$A$505)*(Лист1!$B13=Лист2!$B$2:$B$505),Лист2!$E$2:$E$505)} -> 1633 | H13: =$D13/$E13 -> 168403 | I13: =WEEKNUM($A13,2) -> 18 | J13: =AVERAGEIFS($E$2:$E$505,$I$2:$I$505,$I13,$B$2:$B$505,$B13) -> 18.5 | K13: =$D13/$J13 -> 163851.57 | L13: =AVERAGEIFS($E$2:$E$505,$B$2:$B$505,$B13) -> 20.285714 | M13: =$D13/$L13 -> 149428.01
A14: 43963 | B14: Кемерово | C14: 28219.5 | D14: 2595778.5 | E14: {=_xlfn.XLOOKUP(1, (Лист1!$A14=Лист2!$A$2:$A$505)*(Лист1!$B14=Лист2!$B$2:$B$505),Лист2!$C$2:$C$505)} -> 21 | F14: {=_xlfn.XLOOKUP(1, (Лист1!$A14=Лист2!$A$2:$A$505)*(Лист1!$B14=Лист2!$B$2:$B$505),Лист2!$D$2:$D$505)} -> 1656 | G14: {=_xlfn.XLOOKUP(1, (Лист1!$A14=Лист2!$A$2:$A$505)*(Лист1!$B14=Лист2!$B$2:$B$505),Лист2!$E$2:$E$505)} -> 1516 | H14: =$D14/$E14 -> 123608.5 | I14: =WEEKNUM($A14,2) -> 20 | J14: =AVERAGEIFS($E$2:$E$505,$I$2:$I$505,$I14,$B$2:$B$505,$B14) -> 21 | K14: =$D14/$J14 -> 123608.5 | L14: =AVERAGEIFS($E$2:$E$505,$B$2:$B$505,$B14) -> 20.285714 | M14: =$D14/$L14 -> 127960.91
A15: 43972 | B15: Кемерово | C15: 31272 | D15: 2744382 | E15: {=_xlfn.XLOOKUP(1, (Лист1!$A15=Лист2!$A$2:$A$505)*(Лист1!$B15=Лист2!$B$2:$B$505),Лист2!$C$2:$C$505)} -> 21 | F15: {=_xlfn.XLOOKUP(1, (Лист1!$A15=Лист2!$A$2:$A$505)*(Лист1!$B15=Лист2!$B$2:$B$505),Лист2!$D$2:$D$505)} -> 1787 | G15: {=_xlfn.XLOOKUP(1, (Лист1!$A15=Лист2!$A$2:$A$505)*(Лист1!$B15=Лист2!$B$2:$B$505),Лист2!$E$2:$E$505)} -> 1626 | H15: =$D15/$E15 -> 130684.86 | I15: =WEEKNUM($A15,2) -> 21 | J15: =AVERAGEIFS($E$2:$E$505,$I$2:$I$505,$I15,$B$2:$B$505,$B15) -> 20.857143 | K15: =$D15/$J15 -> 131579.96 | L15: =AVERAGEIFS($E$2:$E$505,$B$2:$B$505,$B15) -> 20.285714 | M15: =$D15/$L15 -> 135286.44
A16: 43971 | B16: Кемерово | C16: 34077 | D16: 2929330.5 | E16: {=_xlfn.XLOOKUP(1, (Лист1!$A16=Лист2!$A$2:$A$505)*(Лист1!$B16=Лист2!$B$2:$B$505),Лист2!$C$2:$C$505)} -> 21 | F16: {=_xlfn.XLOOKUP(1, (Лист1!$A16=Лист2!$A$2:$A$505)*(Лист1!$B16=Лист2!$B$2:$B$505),Лист2!$D$2:$D$505)} -> 1921 | G16: {=_xlfn.XLOOKUP(1, (Лист1!$A16=Лист2!$A$2:$A$505)*(Лист1!$B16=Лист2!$B$2:$B$505),Лист2!$E$2:$E$505)} -> 1767 | H16: =$D16/$E16 -> 139491.93 | I16: =WEEKNUM($A16,2) -> 21 | J16: =AVERAGEIFS($E$2:$E$505,$I$2:$I$505,$I16,$B$2:$B$505,$B16) -> 20.857143 | K16: =$D16/$J16 -> 140447.35 | L16: =AVERAGEIFS($E$2:$E$505,$B$2:$B$505,$B16) -> 20.285714 | M16: =$D16/$L16 -> 144403.62
A17: 43956 | B17: Кемерово | C17: 31566 | D17: 2906763 | E17: {=_xlfn.XLOOKUP(1, (Лист1!$A17=Лист2!$A$2:$A$505)*(Лист1!$B17=Лист2!$B$2:$B$505),Лист2!$C$2:$C$505)} -> 20 | F17: {=_xlfn.XLOOKUP(1, (Лист1!$A17=Лист2!$A$2:$A$505)*(Лист1!$B17=Лист2!$B$2:$B$505),Лист2!$D$2:$D$505)} -> 1773 | G17: {=_xlfn.XLOOKUP(1, (Лист1!$A17=Лист2!$A$2:$A$505)*(Лист1!$B17=Лист2!$B$2:$B$505),Лист2!$E$2:$E$505)} -> 1604 | H17: =$D17/$E17 -> 145338.15 | I17: =WEEKNUM($A17,2) -> 19 | J17: =AVERAGEIFS($E$2:$E$505,$I$2:$I$505,$I17,$B$2:$B$505,$B17) -> 20.571429 | K17: =$D17/$J17 -> 141300.98 | L17: =AVERAGEIFS($E$2:$E$505,$B$2:$B$505,$B17) -> 20.285714 | M17: =$D17/$L17 -> 143291.13
A18: 43949 | B18: Кемерово | C18: 26940 | D18: 2411587.5 | E18: {=_xlfn.XLOOKUP(1, (Лист1!$A18=Лист2!$A$2:$A$505)*(Лист1!$B18=Лист2!$B$2:$B$505),Лист2!$C$2:$C$505)} -> 18 | F18: {=_xlfn.XLOOKUP(1, (Лист1!$A18=Лист2!$A$2:$A$505)*(Лист1!$B18=Лист2!$B$2:$B$505),Лист2!$D$2:$D$505)} -> 1539 | G18: {=_xlfn.XLOOKUP(1, (Лист1!$A18=Лист2!$A$2:$A$505)*(Лист1!$B18=Лист2!$B$2:$B$505),Лист2!$E$2:$E$505)} -> 1404 | H18: =$D18/$E18 -> 133977.08 | I18: =WEEKNUM($A18,2) -> 18 | J18: =AVERAGEIFS($E$2:$E$505,$I$2:$I$505,$I18,$B$2:$B$505,$B18) -> 18.5 | K18: =$D18/$J18 -> 130356.08 | L18: =AVERAGEIFS($E$2:$E$505,$B$2:$B$505,$B18) -> 20.285714 | M18: =$D18/$L18 -> 118881.07
A19: 43964 | B19: Кемерово | C19: 29241 | D19: 2629782 | E19: {=_xlfn.XLOOKUP(1, (Лист1!$A19=Лист2!$A$2:$A$505)*(Лист1!$B19=Лист2!$B$2:$B$505),Лист2!$C$2:$C$505)} -> 21 | F19: {=_xlfn.XLOOKUP(1, (Лист1!$A19=Лист2!$A$2:$A$505)*(Лист1!$B19=Лист2!$B$2:$B$505),Лист2!$D$2:$D$505)} -> 1698 | G19: {=_xlfn.XLOOKUP(1, (Лист1!$A19=Лист2!$A$2:$A$505)*(Лист1!$B19=Лист2!$B$2:$B$505),Лист2!$E$2:$E$505)} -> 1554 | H19: =$D19/$E19 -> 125227.71 | I19: =WEEKNUM($A19,2) -> 20 | J19: =AVERAGEIFS($E$2:$E$505,$I$2:$I$505,$I19,$B$2:$B$505,$B19) -> 21 | K19: =$D19/$J19 -> 125227.71 | L19: =AVERAGEIFS($E$2:$E$505,$B$2:$B$505,$B19) -> 20.285714 | M19: =$D19/$L19 -> 129637.14
A20: 43954 | B20: Кемерово | C20: 26082 | D20: 2434914 | E20: {=_xlfn.XLOOKUP(1, (Лист1!$A20=Лист2!$A$2:$A$505)*(Лист1!$B20=Лист2!$B$2:$B$505),Лист2!$C$2:$C$505)} -> 20 | F20: {=_xlfn.XLOOKUP(1, (Лист1!$A20=Лист2!$A$2:$A$505)*(Лист1!$B20=Лист2!$B$2:$B$505),Лист2!$D$2:$D$505)} -> 1520 | G20: {=_xlfn.XLOOKUP(1, (Лист1!$A20=Лист2!$A$2:$A$505)*(Лист1!$B20=Лист2!$B$2:$B$505),Лист2!$E$2:$E$505)} -> 1373 | H20: =$D20/$E20 -> 121745.7 | I20: =WEEKNUM($A20,2) -> 18 | J20: =AVERAGEIFS($E$2:$E$505,$I$2:$I$505,$I20,$B$2:$B$505,$B20) -> 18.5 | K20: =$D20/$J20 -> 131616.97 | L20: =AVERAGEIFS($E$2:$E$505,$B$2:$B$505,$B20) -> 20.285714 | M20: =$D20/$L20 -> 120030.97
A21: 43957 | B21: Кемерово | C21: 32511 | D21: 2938623 | E21: {=_xlfn.XLOOKUP(1, (Лист1!$A21=Лист2!$A$2:$A$505)*(Лист1!$B21=Лист2!$B$2:$B$505),Лист2!$C$2:$C$505)} -> 20 | F21: {=_xlfn.XLOOKUP(1, (Лист1!$A21=Лист2!$A$2:$A$505)*(Лист1!$B21=Лист2!$B$2:$B$505),Лист2!$D$2:$D$505)} -> 1784 | G21: {=_xlfn.XLOOKUP(1, (Лист1!$A21=Лист2!$A$2:$A$505)*(Лист1!$B21=Лист2!$B$2:$B$505),Лист2!$E$2:$E$505)} -> 1632 | H21: =$D21/$E21 -> 146931.15 | I21: =WEEKNUM($A21,2) -> 19 | J21: =AVERAGEIFS($E$2:$E$505,$I$2:$I$505,$I21,$B$2:$B$505,$B21) -> 20.571429 | K21: =$D21/$J21 -> 142849.73 | L21: =AVERAGEIFS($E$2:$E$505,$B$2:$B$505,$B21) -> 20.285714 | M21: =$D21/$L21 -> 144861.7
A22: 43974 | B22: Кемерово | C22: 42703.5 | D22: 3628726.5 | E22: {=_xlfn.XLOOKUP(1, (Лист1!$A22=Лист2!$A$2:$A$505)*(Лист1!$B22=Лист2!$B$2:$B$505),Лист2!$C$2:$C$505)} -> 21 | F22: {=_xlfn.XLOOKUP(1, (Лист1!$A22=Лист2!$A$2:$A$505)*(Лист1!$B22=Лист2!$B$2:$B$505),Лист2!$D$2:$D$505)} -> 2340 | G22: {=_xlfn.XLOOKUP(1, (Лист1!$A22=Лист2!$A$2:$A$505)*(Лист1!$B22=Лист2!$B$2:$B$505),Лист2!$E$2:$E$505)} -> 2146 | H22: =$D22/$E22 -> 172796.5 | I22: =WEEKNUM($A22,2) -> 21 | J22: =AVERAGEIFS($E$2:$E$505,$I$2:$I$505,$I22,$B$2:$B$505,$B22) -> 20.857143 | K22: =$D22/$J22 -> 173980.04 | L22: =AVERAGEIFS($E$2:$E$505,$B$2:$B$505,$B22) -> 20.285714 | M22: =$D22/$L22 -> 178880.88
... A505: 43983 | B505: Новосибирск | C505: 14238 | D505: 1293219 | E505: {=_xlfn.XLOOKUP(1, (Лист1!$A505=Лист2!$A$2:$A$505)*(Лист1!$B505=Лист2!$B$2:$B$505),Лист2!$C$2:$C$505)} -> 18 | F505: {=_xlfn.XLOOKUP(1, (Лист1!$A505=Лист2!$A$2:$A$505)*(Лист1!$B505=Лист2!$B$2:$B$505),Лист2!$D$2:$D$505)} -> 923 | G505: {=_xlfn.XLOOKUP(1, (Лист1!$A505=Лист2!$A$2:$A$505)*(Лист1!$B505=Лист2!$B$2:$B$505),Лист2!$E$2:$E$505)} -> 824 | H505: =$D505/$E505 -> 71845.5 | I505: =WEEKNUM($A505,2) -> 23 | J505: =AVERAGEIFS($E$2:$E$505,$I$2:$I$505,$I505,$B$2:$B$505,$B505) -> 18 | K505: =$D505/$J505 -> 71845.5 | L505: =AVERAGEIFS($E$2:$E$505,$B$2:$B$505,$B505) -> 16.285714 | M505: =$D505/$L505 -> 79408.184

Sheet Лист2
A1: Дата | B1: Территория | C1: Количество складов | D1: Количество заказов | E1: Количество клиентов
A2: 43949 | B2: Волгоград | C2: 36 | D2: 4923 | E2: 4560
A3: 43949 | B3: Екатеринбург | C3: 31 | D3: 5465 | E3: 5096
A4: 43949 | B4: Казань | C4: 19 | D4: 1846 | E4: 1681
A5: 43949 | B5: Кемерово | C5: 18 | D5: 1539 | E5: 1404
A6: 43949 | B6: Краснодар | C6: 18 | D6: 1505 | E6: 1368
A7: 43949 | B7: Москва Восток | C7: 54 | D7: 12306 | E7: 11532
A8: 43949 | B8: Москва Запад | C8: 59 | D8: 12943 | E8: 12072
A9: 43949 | B9: Нижний Новгород | C9: 17 | D9: 1439 | E9: 1265
A10: 43949 | B10: Новосибирск | C10: 15 | D10: 636 | E10: 547
A11: 43949 | B11: Пермь | C11: 15 | D11: 780 | E11: 690
A12: 43949 | B12: Санкт-Петербург Север | C12: 125 | D12: 20914 | E12: 19479
A13: 43949 | B13: Санкт-Петербург Юг | C13: 128 | D13: 16450 | E13: 15320
... A505: 43983 | B505: Уфа | C505: 6 | D505: 237 | E505: 175

Sheet Сводные таблицы
A3: Общий товарооборот, руб | B3: Недели
A4: Территории | B4: 18 | C4: 19 | D4: 20 | E4: 21 | F4: 22 | G4: 23 | H4: Grand Total
A5: Санкт-Петербург Север | B5: 233059077 | C5: 2.727625e+08 | D5: 269949999 | E5: 2.7553943e+08 | F5: 2.9215505e+08 | G5: 37257840 | H5: 1.3807239e+09 | I5: Топ 3 по доле в общем товарообороте, руб. (доли считать необязательно).
A6: Санкт-Петербург Юг | B6: 176269533 | C6: 2.0812839e+08 | D6: 1.9956962e+08 | E6: 2.0460881e+08 | F6: 2.1926593e+08 | G6: 27770092 | H6: 1.0356124e+09
A7: Москва Запад | B7: 136791225 | C7: 159695760 | D7: 142825023 | E7: 1.5751236e+08 | F7: 1.5785721e+08 | G7: 19465372 | H7: 7.7414695e+08
A8: Москва Восток | B8: 130713645 | C8: 1.5164204e+08 | D8: 135813990 | E8: 149589546 | F8: 151451013 | G8: 18914194 | H8: 738124428
A9: Екатеринбург | B9: 42828758 | C9: 46366010 | D9: 47079842 | E9: 49575288 | F9: 50729186 | G9: 6829921.5 | H9: 2.43409e+08
A10: Волгоград | B10: 36934095 | C10: 43307156 | D10: 41300679 | E10: 44172813 | F10: 46485094 | G10: 5800290 | H10: 218000127
A11: Казань | B11: 17828216 | C11: 20974521 | D11: 23603355 | E11: 26815804 | F11: 27495690 | G11: 3865251 | H11: 120582837
A12: Кемерово | B12: 16029680 | C12: 19479056 | D12: 19724733 | E12: 20915751 | F12: 22579281 | G12: 2945035.5 | H12: 1.0167354e+08
A13: Нижний Новгород | B13: 13145966 | C13: 17149980 | D13: 19963154 | E13: 20713983 | F13: 21605704 | G13: 3013512 | H13: 95592298
A14: Краснодар | B14: 13955985 | C14: 16391856 | D14: 16732521 | E14: 17647479 | F14: 18595773 | G14: 2538967.5 | H14: 85862582
A15: Пермь | B15: 6961020 | C15: 8778597 | D15: 9036316.5 | E15: 10598445 | F15: 11902053 | G15: 1526608.5 | H15: 48803040
A16: Новосибирск | B16: 5746024.5 | C16: 7253572.5 | D16: 7841920.5 | E16: 8990269.5 | F16: 9909624 | G16: 1293219 | H16: 41034630
A17: Ростов-на-Дону | B17: 2008809 | C17: 5892277.5 | D17: 7382458.5 | E17: 8638525.5 | F17: 9328845 | G17: 1565632.5 | H17: 34816548
A18: Тольятти | B18: 4531000.5 | C18: 6093688.5 | D18: 6439392 | E18: 7373379 | F18: 7762362 | G18: 1007742 | H18: 33207564
A19: Тюмень | F19: 4861708.5 | G19: 802447.5 | H19: 5664156
A20: Самара | F20: 2706253.5 | G20: 636345 | H20: 3342598.5
A21: Томск | F21: 493893 | G21: 389013 | H21: 882906
A22: Уфа | F22: 468835.5 | G22: 410892 | H22: 879727.5
A23: Grand Total | B23: 836803032 | C23: 9.8391541e+08 | D23: 9.4726301e+08 | E23: 1.0026919e+09 | F23: 1.0556535e+09 | G23: 1.3603238e+08 | H23: 4.9623592e+09
A27: Общий товарооборот на склад, руб (сред.) | B27: Недели
A28: Территории | B28: 18 | C28: 19 | D28: 20 | E28: 21 | F28: 22 | G28: 23
A29: Москва Восток | B29: 2420623.1 | C29: 2808185.9 | D29: 2515073.9 | E29: 2770176.8 | F29: 2804648.4 | G29: 350262.86 | H29: Топ-3 территорий по товарообороту на склад за последнюю неделю.
A30: Москва Запад | B30: 2318495.3 | C30: 2706707.8 | D30: 2380417 | E30: 2625206 | F30: 2669083.3 | G30: 329921.57
A31: Санкт-Петербург Север | B31: 1864472.6 | C31: 2182100 | D31: 2159600 | E31: 2204315.5 | F31: 2356089.1 | G31: 302909.27
A32: Екатеринбург | B32: 1381572.8 | C32: 1495677.7 | D32: 1518704.6 | E32: 1599202.8 | F32: 1636425.3 | G32: 220320.05
A33: Санкт-Петербург Юг | B33: 1369970.5 | C33: 1613398.4 | D33: 1547051.4 | E33: 1586114.8 | F33: 1699735.9 | G33: 216953.85
A34: Казань | B34: 906519.43 | C34: 1019594.8 | D34: 1123969.3 | E34: 1276943.1 | F34: 1266248.9 | G34: 168054.39
A35: Волгоград | B35: 1025947.1 | C35: 1202976.5 | D35: 1147241.1 | E35: 1227022.6 | F35: 1271076.8 | G35: 156764.59
A36: Нижний Новгород | B36: 710592.73 | C36: 902630.53 | D36: 1050692.3 | E36: 1066160.9 | F36: 1080285.2 | G36: 150675.6
A37: Кемерово | B37: 866469.16 | C37: 946898.53 | D37: 939273 | E37: 1002810 | F37: 1120957.2 | G37: 140239.79
A38: Краснодар | B38: 747642.05 | C38: 862729.26 | D38: 880659 | E38: 928814.68 | F38: 923194.4 | G38: 120903.21
A39: Тюмень | F39: 694529.79 | G39: 114635.36
A40: Тольятти | B40: 453100.05 | C40: 609368.85 | D40: 643939.2 | E40: 737337.9 | F40: 776236.2 | G40: 100774.2
A41: Ростов-на-Дону | B41: 133920.6 | C41: 392818.5 | D41: 492163.9 | E41: 575901.7 | F41: 599100.14 | G41: 97852.031
A42: Пермь | B42: 464068 | C42: 585239.8 | D42: 602421.1 | E42: 639561.34 | F42: 700120.76 | G42: 89800.5
A43: Новосибирск | B43: 383068.3 | C43: 483571.5 | D43: 503609.57 | E43: 515835.14 | F43: 550534.67 | G43: 71845.5
A44: Уфа | F44: 78139.25 | G44: 68482
A45: Томск | F45: 54877 | G45: 43223.667
...
